<?xml version="1.0" ?>

<robot name="cf21">



<!-- ======================================================================
This URDF file is adapted to the CrazyFlie hardware and firmware setup.
In contrast to cf2x.urdf, the motor IDs have a different order.
====================================================================== -->
  <!-- Note: original parameters: thrust2weight="2.25" -->
  <properties arm="0.0397" kf="3.16e-10" km="7.94e-12" thrust2weight="1.8" max_speed_kmh="30" gnd_eff_coeff="11.36859" prop_radius="2.31348e-2" drag_coeff_xy="9.1785e-7" drag_coeff_z="10.311e-7" dw_coeff_1="2267.18" dw_coeff_2=".16" dw_coeff_3="-.11" />

  <link name="base_link">

    <inertial>
      <origin rpy="0 0 0" xyz="0 0 0"/>
      <mass value="0.030"/>
      <!--==============================
        In case, you run into the error:
        "Bad inertia tensor properties, setting inertia to zero for link: ...",
        please regard the following properties:
            - principalInertiaX < (principalInertiaY + principalInertiaZ)
			- principalInertiaY > 0
			- principalInertiaY < (principalInertiaX + principalInertiaZ)
			- principalInertiaZ > 0
			- principalInertiaZ < (principalInertiaX + principalInertiaY))
	    ================================
      -->
      <inertia ixx="1.33e-5" ixy="0.0" ixz="0.0" iyy="1.33e-5" iyz="0.0" izz="2.64e-5"/>
    </inertial>

    <!-- links>
      <carlos url="https://arxiv.org/pdf/1608.05786.pdf" />
      <julian url="http://mikehamer.info/assets/papers/Crazyflie%20Modelling.pdf" />
      <mit url="http://groups.csail.mit.edu/robotics-center/public_papers/Landry15.pdf" />
    </links -->

    <visual>
      <origin rpy="0 0 55" xyz="0 0 0"/>
      <geometry>
        <mesh filename="meshes/cf2withoutRotors.dae" scale="0.86 0.86 0.86"/>
      </geometry>
      <material name="grey">
        <color rgba=".5 .5 .5 1"/>
      </material>
    </visual>

    <collision>
      <origin rpy="0 0 0" xyz="0 0 0"/>
      <geometry>
        <cylinder radius=".06" length=".025"/>
      </geometry>
    </collision>

  </link>

  <joint name="prop1_joint" type="continuous">
    <origin rpy="0 0 0" xyz="0.028 -0.028 0.0108"/>
    <parent link="base_link"/>
    <child link="m1_link"/>
    <axis xyz="0 0 -1"/>
  </joint>
  <link name="m1_link">
    <inertial>
      <mass value="1.0e-9"/>
      <!-- [kg] -->
      <inertia ixx="1.0e-09" ixy="0.0" ixz="0.0" iyy="1.0e-09" iyz="0.0" izz="1.0e-09"/>
    </inertial>
    <visual>
      <material name="dark_gray"/>
      <geometry>
         <mesh filename="meshes/ccw_prop.stl" scale="1 1 1"/>
      </geometry>
    </visual>
    <collision>
      <geometry>
        <cylinder length="0.005" radius="0.015"/>
      </geometry>
    </collision>
  </link>


  <joint name="prop2_joint" type="continuous">
    <origin rpy="0 0 0" xyz="-0.028 -0.028 0.0108"/>
    <parent link="base_link"/>
    <child link="m2_link"/>
    <axis xyz="0 0 1"/>
  </joint>
   <link name="m2_link">
    <inertial>
      <mass value="1.0e-9"/>
      <!-- [kg] -->
      <inertia ixx="1.0e-09" ixy="0.0" ixz="0.0" iyy="1.0e-09" iyz="0.0" izz="1.0e-09"/>
    </inertial>
    <visual>
      <material name="dark_gray"/>
      <geometry>
         <mesh filename="meshes/cw_prop.stl" scale="1 1 1"/>
      </geometry>
    </visual>
    <collision>
      <geometry>
        <cylinder length="0.005" radius="0.015"/>
      </geometry>
    </collision>
  </link>


  <joint name="prop3_joint" type="continuous">
    <origin rpy="0 0 0" xyz="-0.028 0.028 0.0108"/>
    <parent link="base_link"/>
    <child link="m3_link"/>
    <axis xyz="0 0 -1"/>
  </joint>
  <link name="m3_link">
    <inertial>
      <mass value="1.0e-9"/>
      <!-- [kg] -->
      <inertia ixx="1.0e-09" ixy="0.0" ixz="0.0" iyy="1.0e-09" iyz="0.0" izz="1.0e-09"/>
    </inertial>
    <visual>
      <material name="dark_gray"/>
      <geometry>
         <mesh filename="meshes/ccw_prop.stl" scale="1 1 1"/>
      </geometry>
    </visual>
    <collision>
      <geometry>
        <cylinder length="0.005" radius="0.015"/>
      </geometry>
    </collision>
  </link>

  <joint name="prop4_joint" type="continuous">
    <origin rpy="0 0 0" xyz="0.028 0.028 0.0108"/>
    <parent link="base_link"/>
    <child link="m4_link"/>
    <axis xyz="0 0 1"/>
  </joint>
  <link name="m4_link">
    <inertial>
      <mass value="1.0e-9"/>
      <!-- [kg] -->
      <inertia ixx="1.0e-09" ixy="0.0" ixz="0.0" iyy="1.0e-09" iyz="0.0" izz="1.0e-09"/>
    </inertial>
    <visual>
      <material name="dark_gray"/>
      <geometry>
          <mesh filename="meshes/cw_prop.stl" scale="1 1 1"/>
      </geometry>
    </visual>
    <collision>
      <geometry>
        <cylinder length="0.005" radius="0.015"/>
      </geometry>
    </collision>
  </link>

  <link name="center_of_mass_link">
    <inertial>
      <origin rpy="0 0 0" xyz="0 0 0"/>
      <mass value="0"/>
      <inertia ixx="0" ixy="0" ixz="0" iyy="0" iyz="0" izz="0"/>
    </inertial>
  </link>
  <joint name="center_of_mass_joint" type="continuous">
    <parent link="base_link"/>
    <child link="center_of_mass_link"/>
    <axis xyz="0 0 1"/>
  </joint>
  <material name="dark_gray">
    <color rgba="0.3 0.3 0.3 1"/>
  </material>
</robot>

